Workbook

Sheet Start Here
A1: Project Earlobe — cost-out & ROI model (Curious & Creative Network)
A2: Prices as of Oct 2026 — verify before buying. Built by finance/build_cost_model.py.
A4: How to use
A5: 1. | B5: Change inputs only on the Assumptions tab (blue text; yellow = key levers).
A6: 2. | B6: Pick the revenue case (Conservative / Base / Optimistic) at the top of Assumptions.
A7: 3. | B7: Read results on Scenarios (monthly steady state), 12-Month Plan (cash + payback) and Sensitivity.
A8: Colors | B8: Blue = input · Black = formula · Green = link to another tab · Yellow fill = key lever
A9: Scenarios | B9: Test = Columbia + LA + national shows · Wave 1 = + NYC/Chicago/more, first niche feeds · Scale = 25 markets, 150+ shows · Dominate = 100 markets, ~700 shows
A10: Honesty note | B10: Downloads, CPM fill and sponsor counts are estimates until real analytics arrive. Replace them with actuals monthly; the Finance/Bookkeeping Reporter agent does this.
A12: Headline (current revenue case) | C12: Test markets | D12: Wave 1 | E12: Scale | F12: Dominate
A13: Shows | C13: =Scenarios!C12 -> 7 | D13: =Scenarios!D12 -> 27 | E13: =Scenarios!E12 -> 157 | F13: =Scenarios!F12 -> 693
A14: Episodes / month | C14: =Scenarios!C21 -> 125.1 | D14: =Scenarios!D21 -> 444.3 | E14: =Scenarios!E21 -> 2278.5 | F14: =Scenarios!F21 -> 9689
A15: Downloads / month | C15: =Scenarios!C37 -> 43024 | D15: =Scenarios!D37 -> 158928 | E15: =Scenarios!E37 -> 874337.5 | F15: =Scenarios!F37 -> 4256910
A16: Total monthly cost | C16: =Scenarios!C33 -> 653.40055 | D16: =Scenarios!D33 -> 2052.6273 | E16: =Scenarios!E33 -> 7093.3931 | F16: =Scenarios!F33 -> 20772.252
A17: Total monthly revenue | C17: =Scenarios!C44 -> 4015.8732 | D17: =Scenarios!D44 -> 13203.323 | E17: =Scenarios!E44 -> 60812.165 | F17: =Scenarios!F44 -> 275573.52
A18: Net / month | C18: =Scenarios!C45 -> 3362.4727 | D18: =Scenarios!D45 -> 11150.696 | E18: =Scenarios!E45 -> 53718.772 | F18: =Scenarios!F45 -> 254801.27
A19: Network-only net / month (no B2B/API/services) | C19: =Scenarios!C50 -> 362.47265 | D19: =Scenarios!D50 -> 3150.6961 | E19: =Scenarios!E50 -> 30218.772 | F19: =Scenarios!F50 -> 180301.27
A21: Payback month (12-Month Plan) | C21: ='12-Month Plan'!D20 -> 4
A22: Max cash needed before payback | C22: ='12-Month Plan'!D21 -> -3021.8132
A23: Year-1 ROI | C23: ='12-Month Plan'!D24 -> 4.4985466

Sheet Assumptions
A1: Assumptions — every input lives here (blue = editable)
A2: Prices as of Oct 2026 — verify before buying. (inference) = our estimate, not a quoted price.
A4: Model selectors
A5: Revenue case (1 = Conservative, 2 = Base, 3 = Optimistic) | B5: 2
A6: Scenario used for unit economics (1 = Test … 4 = Dominate) | B6: 2
A8: Global
A9: Input | B9: Value | C9: Unit | D9: Source / note
A10: Spoken characters per audio minute | B10: 1000 | C10: chars/min | D10: ElevenLabs guidance ~1,000 chars ≈ 1 min (F-TTS)
A11: ElevenLabs credits per character | B11: 1 | C11: credits | D11: 1.0 for highest-quality voices; some faster models bill ~0.5 (F-TTS) — verify per model
A12: Weekdays per month | B12: 21.7 | C12: days | D12: 365×5/7/12
A13: Days per month | B13: 30.4 | C13: days
A14: Prompt-caching savings on LLM input | B14: 0.15 | C14: % | D14: (inference) system prompts + rubrics cached; cache reads bill at 0.1× input
A15: Share of episodes that need a REWRITE loop | B15: 0.3 | C15: % | D15: (inference) tune from gate logs after launch
A16: Cost of one rewrite loop vs a first pass | B16: 0.6 | C16: x | D16: (inference) writer + re-check of changed claims
A17: Batch API discount (evergreen only) | B17: 0.5 | C17: % | D17: Anthropic Message Batches: 50% off (F-LLM)
A19: Claude API list prices (per million tokens)
A20: Tier | B20: Input $/M | C20: Output $/M | D20: Source / note
A21: opus | B21: 4 | C21: 20 | D21: Anthropic list price, Oct 2026 (F-LLM)
A22: sonnet | B22: 2 | C22: 10 | D22: Anthropic list price, Oct 2026 (F-LLM)
A23: haiku | B23: 0.1 | C23: 0.5 | D23: Anthropic list price, Oct 2026 (F-LLM)
A24: Web search, $ per 1,000 searches | B24: 10 | D24: Anthropic web search tool (F-LLM)
A26: Per-episode agent work — baseline 7-minute verified news brief
A27: Agent step | B27: Tier | C27: Input tokens | D27: Output tokens | E27: Web searches | F27: Cost / episode
A28: Story triage (Story Desk) | B28: haiku | C28: 60000 | D28: 4000 | E28: 0 | F28: =C28/1000000*IF(B28="opus",Assumptions!$B$21,IF(B28="sonnet",Assumptions!$B$22,Assumptions!$B$23))+D28/1000000*IF(B28="opus",Assumptions!$C$21,IF(B28="sonnet",Assumptions!$C$22,Assumptions!$C$23))+E28/1000*Assumptions!$B$24 -> 0.008
A29: Producer / scriptwriter | B29: opus | C29: 40000 | D29: 10000 | E29: 0 | F29: =C29/1000000*IF(B29="opus",Assumptions!$B$21,IF(B29="sonnet",Assumptions!$B$22,Assumptions!$B$23))+D29/1000000*IF(B29="opus",Assumptions!$C$21,IF(B29="sonnet",Assumptions!$C$22,Assumptions!$C$23))+E29/1000*Assumptions!$B$24 -> 0.36
A30: Claim extractor | B30: opus | C30: 8000 | D30: 4000 | E30: 0 | F30: =C30/1000000*IF(B30="opus",Assumptions!$B$21,IF(B30="sonnet",Assumptions!$B$22,Assumptions!$B$23))+D30/1000000*IF(B30="opus",Assumptions!$C$21,IF(B30="sonnet",Assumptions!$C$22,Assumptions!$C$23))+E30/1000*Assumptions!$B$24 -> 0.112
A31: Source verifier (blind, web search) | B31: opus | C31: 150000 | D31: 12000 | E31: 20 | F31: =C31/1000000*IF(B31="opus",Assumptions!$B$21,IF(B31="sonnet",Assumptions!$B$22,Assumptions!$B$23))+D31/1000000*IF(B31="opus",Assumptions!$C$21,IF(B31="sonnet",Assumptions!$C$22,Assumptions!$C$23))+E31/1000*Assumptions!$B$24 -> 1.04
A32: Fact checker | B32: opus | C32: 40000 | D32: 6000 | E32: 0 | F32: =C32/1000000*IF(B32="opus",Assumptions!$B$21,IF(B32="sonnet",Assumptions!$B$22,Assumptions!$B$23))+D32/1000000*IF(B32="opus",Assumptions!$C$21,IF(B32="sonnet",Assumptions!$C$22,Assumptions!$C$23))+E32/1000*Assumptions!$B$24 -> 0.28
A33: Bias checker | B33: sonnet | C33: 10000 | D33: 3000 | E33: 0 | F33: =C33/1000000*IF(B33="opus",Assumptions!$B$21,IF(B33="sonnet",Assumptions!$B$22,Assumptions!$B$23))+D33/1000000*IF(B33="opus",Assumptions!$C$21,IF(B33="sonnet",Assumptions!$C$22,Assumptions!$C$23))+E33/1000*Assumptions!$B$24 -> 0.05
A34: Legal / defamation screener | B34: opus | C34: 10000 | D34: 3000 | E34: 0 | F34: =C34/1000000*IF(B34="opus",Assumptions!$B$21,IF(B34="sonnet",Assumptions!$B$22,Assumptions!$B$23))+D34/1000000*IF(B34="opus",Assumptions!$C$21,IF(B34="sonnet",Assumptions!$C$22,Assumptions!$C$23))+E34/1000*Assumptions!$B$24 -> 0.1
A35: Copywriter (title, notes, social) | B35: sonnet | C35: 8000 | D35: 3000 | E35: 0 | F35: =C35/1000000*IF(B35="opus",Assumptions!$B$21,IF(B35="sonnet",Assumptions!$B$22,Assumptions!$B$23))+D35/1000000*IF(B35="opus",Assumptions!$C$21,IF(B35="sonnet",Assumptions!$C$22,Assumptions!$C$23))+E35/1000*Assumptions!$B$24 -> 0.046
A36: Disclosure + QA listener | B36: haiku | C36: 6000 | D36: 1500 | E36: 0 | F36: =C36/1000000*IF(B36="opus",Assumptions!$B$21,IF(B36="sonnet",Assumptions!$B$22,Assumptions!$B$23))+D36/1000000*IF(B36="opus",Assumptions!$C$21,IF(B36="sonnet",Assumptions!$C$22,Assumptions!$C$23))+E36/1000*Assumptions!$B$24 -> 0.00135
A37: Baseline LLM + search cost per episode (before caching/rewrites) | F37: =SUM(F28:F36) -> 1.99735
A39: Show types
A40: Show type | B40: Minutes / episode | C40: Episodes / month / show | D40: LLM work vs baseline | E40: Batch-eligible (1/0) | F40: Ad slots / episode | G40: Downloads / episode (base, test stage)
A41: Local daily brief | B41: 7 | C41: 21.7 | D41: 1 | E41: 0 | F41: 2 | G41: 150 | H41: (inference) — replace with real analytics after launch
A42: Breaking Desk feed | B42: 3 | C42: 30 | D42: 0.8 | E42: 0 | F42: 1 | G42: 600 | H42: (inference) — replace with real analytics after launch
A43: Courts roundup | B43: 10 | C43: 21.7 | D43: 1.3 | E43: 0 | F43: 2 | G43: 120 | H43: (inference) — replace with real analytics after launch
A44: Case Tracker (weekly + flashes) | B44: 20 | C44: 8.3 | D44: 1.8 | E44: 0 | F44: 3 | G44: 400 | H44: (inference) — replace with real analytics after launch
A45: Cold Case Files | B45: 22 | C45: 8.7 | D45: 2.2 | E45: 1 | F45: 3 | G45: 700 | H45: (inference) — replace with real analytics after launch
...

Sheet Unit Economics
A1: Unit economics — cost and break-even per episode
A2: Voice cost uses the effective $/credit of the scenario chosen on Assumptions (unit-economics scenario).
A4: Show type | B4: Minutes | C4: LLM + search $ / ep | D4: Voice $ / ep | E4: Variable cost $ / ep | F4: Revenue $ per download | G4: Break-even downloads / ep | H4: Base downloads / ep (scenario) | I4: Margin $ / ep at base downloads
A5: Local daily brief | B5: =Assumptions!B41 -> 7 | C5: =Assumptions!$F$37*Assumptions!D41*(1-Assumptions!$B$14)*(1-Assumptions!E41*Assumptions!$B$17)*(1+Assumptions!$B$15*Assumptions!$B$16) -> 2.0033421 | D5: =B5*Assumptions!$B$10*Assumptions!$B$11*INDEX(Scenarios!$C$30:$F$30,Assumptions!$B$6) -> 1.9060454 | E5: =C5+D5 -> 3.9093875 | F5: =Assumptions!F41*INDEX(Assumptions!$B$73:$D$73,Assumptions!$B$5)/1000*INDEX(Assumptions!$B$74:$D$74,Assumptions!$B$5)*INDEX(Assumptions!$B$75:$D$75,Assumptions!$B$5) -> 0.0108 | G5: =IF(F5=0,0,E5/F5) -> 361.98032 | H5: =Assumptions!G41*INDEX(Assumptions!$B$58:$E$58,Assumptions!$B$6) -> 225 | I5: =H5*F5-E5 -> -1.4793875
A6: Breaking Desk feed | B6: =Assumptions!B42 -> 3 | C6: =Assumptions!$F$37*Assumptions!D42*(1-Assumptions!$B$14)*(1-Assumptions!E42*Assumptions!$B$17)*(1+Assumptions!$B$15*Assumptions!$B$16) -> 1.6026736 | D6: =B6*Assumptions!$B$10*Assumptions!$B$11*INDEX(Scenarios!$C$30:$F$30,Assumptions!$B$6) -> 0.81687662 | E6: =C6+D6 -> 2.4195503 | F6: =Assumptions!F42*INDEX(Assumptions!$B$73:$D$73,Assumptions!$B$5)/1000*INDEX(Assumptions!$B$74:$D$74,Assumptions!$B$5)*INDEX(Assumptions!$B$75:$D$75,Assumptions!$B$5) -> 0.0054 | G6: =IF(F6=0,0,E6/F6) -> 448.06486 | H6: =Assumptions!G42*INDEX(Assumptions!$B$58:$E$58,Assumptions!$B$6) -> 900 | I6: =H6*F6-E6 -> 2.4404497
A7: Courts roundup | B7: =Assumptions!B43 -> 10 | C7: =Assumptions!$F$37*Assumptions!D43*(1-Assumptions!$B$14)*(1-Assumptions!E43*Assumptions!$B$17)*(1+Assumptions!$B$15*Assumptions!$B$16) -> 2.6043447 | D7: =B7*Assumptions!$B$10*Assumptions!$B$11*INDEX(Scenarios!$C$30:$F$30,Assumptions!$B$6) -> 2.7229221 | E7: =C7+D7 -> 5.3272667 | F7: =Assumptions!F43*INDEX(Assumptions!$B$73:$D$73,Assumptions!$B$5)/1000*INDEX(Assumptions!$B$74:$D$74,Assumptions!$B$5)*INDEX(Assumptions!$B$75:$D$75,Assumptions!$B$5) -> 0.0108 | G7: =IF(F7=0,0,E7/F7) -> 493.26544 | H7: =Assumptions!G43*INDEX(Assumptions!$B$58:$E$58,Assumptions!$B$6) -> 180 | I7: =H7*F7-E7 -> -3.3832667
A8: Case Tracker (weekly + flashes) | B8: =Assumptions!B44 -> 20 | C8: =Assumptions!$F$37*Assumptions!D44*(1-Assumptions!$B$14)*(1-Assumptions!E44*Assumptions!$B$17)*(1+Assumptions!$B$15*Assumptions!$B$16) -> 3.6060157 | D8: =B8*Assumptions!$B$10*Assumptions!$B$11*INDEX(Scenarios!$C$30:$F$30,Assumptions!$B$6) -> 5.4458441 | E8: =C8+D8 -> 9.0518598 | F8: =Assumptions!F44*INDEX(Assumptions!$B$73:$D$73,Assumptions!$B$5)/1000*INDEX(Assumptions!$B$74:$D$74,Assumptions!$B$5)*INDEX(Assumptions!$B$75:$D$75,Assumptions!$B$5) -> 0.0162 | G8: =IF(F8=0,0,E8/F8) -> 558.75678 | H8: =Assumptions!G44*INDEX(Assumptions!$B$58:$E$58,Assumptions!$B$6) -> 600 | I8: =H8*F8-E8 -> 0.6681402
A9: Cold Case Files | B9: =Assumptions!B45 -> 22 | C9: =Assumptions!$F$37*Assumptions!D45*(1-Assumptions!$B$14)*(1-Assumptions!E45*Assumptions!$B$17)*(1+Assumptions!$B$15*Assumptions!$B$16) -> 2.2036763 | D9: =B9*Assumptions!$B$10*Assumptions!$B$11*INDEX(Scenarios!$C$30:$F$30,Assumptions!$B$6) -> 5.9904285 | E9: =C9+D9 -> 8.1941048 | F9: =Assumptions!F45*INDEX(Assumptions!$B$73:$D$73,Assumptions!$B$5)/1000*INDEX(Assumptions!$B$74:$D$74,Assumptions!$B$5)*INDEX(Assumptions!$B$75:$D$75,Assumptions!$B$5) -> 0.0162 | G9: =IF(F9=0,0,E9/F9) -> 505.80894 | H9: =Assumptions!G45*INDEX(Assumptions!$B$58:$E$58,Assumptions!$B$6) -> 1050 | I9: =H9*F9-E9 -> 8.8158952
A10: Archive series (History of Hollywood, hometown) | B10: =Assumptions!B46 -> 18 | C10: =Assumptions!$F$37*Assumptions!D46*(1-Assumptions!$B$14)*(1-Assumptions!E46*Assumptions!$B$17)*(1+Assumptions!$B$15*Assumptions!$B$16) -> 1.8030078 | D10: =B10*Assumptions!$B$10*Assumptions!$B$11*INDEX(Scenarios!$C$30:$F$30,Assumptions!$B$6) -> 4.9012597 | E10: =C10+D10 -> 6.7042675 | F10: =Assumptions!F46*INDEX(Assumptions!$B$73:$D$73,Assumptions!$B$5)/1000*INDEX(Assumptions!$B$74:$D$74,Assumptions!$B$5)*INDEX(Assumptions!$B$75:$D$75,Assumptions!$B$5) -> 0.0162 | G10: =IF(F10=0,0,E10/F10) -> 413.84368 | H10: =Assumptions!G46*INDEX(Assumptions!$B$58:$E$58,Assumptions!$B$6) -> 750 | I10: =H10*F10-E10 -> 5.4457325
A11: Hyper-specific always-on feed | B11: =Assumptions!B47 -> 5 | C11: =Assumptions!$F$37*Assumptions!D47*(1-Assumptions!$B$14)*(1-Assumptions!E47*Assumptions!$B$17)*(1+Assumptions!$B$15*Assumptions!$B$16) -> 1.2020052 | D11: =B11*Assumptions!$B$10*Assumptions!$B$11*INDEX(Scenarios!$C$30:$F$30,Assumptions!$B$6) -> 1.361461 | E11: =C11+D11 -> 2.5634663 | F11: =Assumptions!F47*INDEX(Assumptions!$B$73:$D$73,Assumptions!$B$5)/1000*INDEX(Assumptions!$B$74:$D$74,Assumptions!$B$5)*INDEX(Assumptions!$B$75:$D$75,Assumptions!$B$5) -> 0.0054 | G11: =IF(F11=0,0,E11/F11) -> 474.71597 | H11: =Assumptions!G47*INDEX(Assumptions!$B$58:$E$58,Assumptions!$B$6) -> 90 | I11: =H11*F11-E11 -> -2.0774663
A13: Read this as: an episode pays for itself once it reaches the break-even downloads from ads alone. Sponsors, B2B, API and services revenue sit on top (Scenarios tab).

Sheet Scenarios
A1: Scenarios — monthly steady state
A2: Revenue case set on Assumptions. All values per month.
A3: Line | C3: Test markets | D3: Wave 1 | E3: Scale | F3: Dominate
A4: Shows
A5: Local daily brief | C5: =Assumptions!B51 -> 2 | D5: =Assumptions!C51 -> 6 | E5: =Assumptions!D51 -> 25 | F5: =Assumptions!E51 -> 100
A6: Breaking Desk feed | C6: =Assumptions!B52 -> 1 | D6: =Assumptions!C52 -> 2 | E6: =Assumptions!D52 -> 3 | F6: =Assumptions!E52 -> 5
A7: Courts roundup | C7: =Assumptions!B53 -> 1 | D7: =Assumptions!C53 -> 3 | E7: =Assumptions!D53 -> 10 | F7: =Assumptions!E53 -> 30
A8: Case Tracker (weekly + flashes) | C8: =Assumptions!B54 -> 1 | D8: =Assumptions!C54 -> 1 | E8: =Assumptions!D54 -> 2 | F8: =Assumptions!E54 -> 4
A9: Cold Case Files | C9: =Assumptions!B55 -> 1 | D9: =Assumptions!C55 -> 1 | E9: =Assumptions!D55 -> 2 | F9: =Assumptions!E55 -> 4
A10: Archive series (History of Hollywood, hometown) | C10: =Assumptions!B56 -> 1 | D10: =Assumptions!C56 -> 4 | E10: =Assumptions!D56 -> 15 | F10: =Assumptions!E56 -> 50
A11: Hyper-specific always-on feed | C11: =Assumptions!B57 -> 0 | D11: =Assumptions!C57 -> 10 | E11: =Assumptions!D57 -> 100 | F11: =Assumptions!E57 -> 500
A12: Total shows | C12: =SUM(C5:C11) -> 7 | D12: =SUM(D5:D11) -> 27 | E12: =SUM(E5:E11) -> 157 | F12: =SUM(F5:F11) -> 693
A13: Episodes per month
A14: Local daily brief | C14: =C5*Assumptions!$C$41 -> 43.4 | D14: =D5*Assumptions!$C$41 -> 130.2 | E14: =E5*Assumptions!$C$41 -> 542.5 | F14: =F5*Assumptions!$C$41 -> 2170
A15: Breaking Desk feed | C15: =C6*Assumptions!$C$42 -> 30 | D15: =D6*Assumptions!$C$42 -> 60 | E15: =E6*Assumptions!$C$42 -> 90 | F15: =F6*Assumptions!$C$42 -> 150
A16: Courts roundup | C16: =C7*Assumptions!$C$43 -> 21.7 | D16: =D7*Assumptions!$C$43 -> 65.1 | E16: =E7*Assumptions!$C$43 -> 217 | F16: =F7*Assumptions!$C$43 -> 651
A17: Case Tracker (weekly + flashes) | C17: =C8*Assumptions!$C$44 -> 8.3 | D17: =D8*Assumptions!$C$44 -> 8.3 | E17: =E8*Assumptions!$C$44 -> 16.6 | F17: =F8*Assumptions!$C$44 -> 33.2
A18: Cold Case Files | C18: =C9*Assumptions!$C$45 -> 8.7 | D18: =D9*Assumptions!$C$45 -> 8.7 | E18: =E9*Assumptions!$C$45 -> 17.4 | F18: =F9*Assumptions!$C$45 -> 34.8
A19: Archive series (History of Hollywood, hometown) | C19: =C10*Assumptions!$C$46 -> 13 | D19: =D10*Assumptions!$C$46 -> 52 | E19: =E10*Assumptions!$C$46 -> 195 | F19: =F10*Assumptions!$C$46 -> 650
A20: Hyper-specific always-on feed | C20: =C11*Assumptions!$C$47 -> 0 | D20: =D11*Assumptions!$C$47 -> 120 | E20: =E11*Assumptions!$C$47 -> 1200 | F20: =F11*Assumptions!$C$47 -> 6000
A21: Total episodes / month | C21: =SUM(C14:C20) -> 125.1 | D21: =SUM(D14:D20) -> 444.3 | E21: =SUM(E14:E20) -> 2278.5 | F21: =SUM(F14:F20) -> 9689
A22: Audio minutes / month | C22: =C14*Assumptions!$B$41+C15*Assumptions!$B$42+C16*Assumptions!$B$43+C17*Assumptions!$B$44+C18*Assumptions!$B$45+C19*Assumptions!$B$46+C20*Assumptions!$B$47 -> 1202.2 | D22: =D14*Assumptions!$B$41+D15*Assumptions!$B$42+D16*Assumptions!$B$43+D17*Assumptions!$B$44+D18*Assumptions!$B$45+D19*Assumptions!$B$46+D20*Assumptions!$B$47 -> 3635.8 | E22: =E14*Assumptions!$B$41+E15*Assumptions!$B$42+E16*Assumptions!$B$43+E17*Assumptions!$B$44+E18*Assumptions!$B$45+E19*Assumptions!$B$46+E20*Assumptions!$B$47 -> 16462.3 | F22: =F14*Assumptions!$B$41+F15*Assumptions!$B$42+F16*Assumptions!$B$43+F17*Assumptions!$B$44+F18*Assumptions!$B$45+F19*Assumptions!$B$46+F20*Assumptions!$B$47 -> 65279.6
A23: Voice credits needed / month | C23: =C22*Assumptions!$B$10*Assumptions!$B$11 -> 1202200 | D23: =D22*Assumptions!$B$10*Assumptions!$B$11 -> 3635800 | E23: =E22*Assumptions!$B$10*Assumptions!$B$11 -> 16462300 | F23: =F22*Assumptions!$B$10*Assumptions!$B$11 -> 65279600
A26: ElevenLabs plan price | C26: =INDEX(Assumptions!$B$62:$B$66,MATCH(Assumptions!B$68,Assumptions!$A$62:$A$66,0)) -> 99 | D26: =INDEX(Assumptions!$B$62:$B$66,MATCH(Assumptions!C$68,Assumptions!$A$62:$A$66,0)) -> 990 | E26: =INDEX(Assumptions!$B$62:$B$66,MATCH(Assumptions!D$68,Assumptions!$A$62:$A$66,0)) -> 3000 | F26: =INDEX(Assumptions!$B$62:$B$66,MATCH(Assumptions!E$68,Assumptions!$A$62:$A$66,0)) -> 3000
A27: Plan credits included | C27: =INDEX(Assumptions!$C$62:$C$66,MATCH(Assumptions!B$68,Assumptions!$A$62:$A$66,0)) -> 600000 | D27: =INDEX(Assumptions!$C$62:$C$66,MATCH(Assumptions!C$68,Assumptions!$A$62:$A$66,0)) -> 6000000 | E27: =INDEX(Assumptions!$C$62:$C$66,MATCH(Assumptions!D$68,Assumptions!$A$62:$A$66,0)) -> 30000000 | F27: =INDEX(Assumptions!$C$62:$C$66,MATCH(Assumptions!E$68,Assumptions!$A$62:$A$66,0)) -> 30000000
A28: Overage credits | C28: =MAX(0,C23-C27) -> 602200 | D28: =MAX(0,D23-D27) -> 0 | E28: =MAX(0,E23-E27) -> 0 | F28: =MAX(0,F23-F27) -> 35279600
A29: Voice (ElevenLabs) cost / month | C29: =C26+C28/1000*Assumptions!B$69 -> 189.33 | D29: =D26+D28/1000*Assumptions!C$69 -> 990 | E29: =E26+E28/1000*Assumptions!D$69 -> 3000 | F29: =F26+F28/1000*Assumptions!E$69 -> 5116.776
A30: Effective $ per voice credit | C30: =IF(C23=0,0,C29/C23) -> 0.00015748628 | D30: =IF(D23=0,0,D29/D23) -> 0.00027229221 | E30: =IF(E23=0,0,E29/E23) -> 0.00018223456 | F30: =IF(F23=0,0,F29/F23) -> 7.8382466e-05
A31: Claude API (agents + web search) / month | C31: =C14*'Unit Economics'!$C$5+C15*'Unit Economics'!$C$6+C16*'Unit Economics'!$C$7+C17*'Unit Economics'!$C$8+C18*'Unit Economics'!$C$9+C19*'Unit Economics'!$C$10+C20*'Unit Economics'!$C$11 -> 264.08055 | D31: =D14*'Unit Economics'!$C$5+D15*'Unit Economics'!$C$6+D16*'Unit Economics'!$C$7+D17*'Unit Economics'!$C$8+D18*'Unit Economics'!$C$9+D19*'Unit Economics'!$C$10+D20*'Unit Economics'!$C$11 -> 813.63734 | E31: =E14*'Unit Economics'!$C$5+E15*'Unit Economics'!$C$6+E16*'Unit Economics'!$C$7+E17*'Unit Economics'!$C$8+E18*'Unit Economics'!$C$9+E19*'Unit Economics'!$C$10+E20*'Unit Economics'!$C$11 -> 3688.3931 | F31: =F14*'Unit Economics'!$C$5+F15*'Unit Economics'!$C$6+F16*'Unit Economics'!$C$7+F17*'Unit Economics'!$C$8+F18*'Unit Economics'!$C$9+F19*'Unit Economics'!$C$10+F20*'Unit Economics'!$C$11 -> 14863.476
A32: Fixed operating costs / month (Cost Lines) | C32: ='Cost Lines'!J18 -> 199.99 | D32: ='Cost Lines'!K18 -> 248.99 | E32: ='Cost Lines'!L18 -> 405 | F32: ='Cost Lines'!M18 -> 792
A33: TOTAL MONTHLY COST | C33: =C29+C31+C32 -> 653.40055 | D33: =D29+D31+D32 -> 2052.6273 | E33: =E29+E31+E32 -> 7093.3931 | F33: =F29+F31+F32 -> 20772.252
A34: Cost per episode (all-in) | C34: =IF(C21=0,0,C33/C21) -> 5.223026 | D34: =IF(D21=0,0,D33/D21) -> 4.619913 | E34: =IF(E21=0,0,E33/E21) -> 3.1131855 | F34: =IF(F21=0,0,F33/F21) -> 2.1439005
A36: Audience & revenue
A37: Downloads / month | C37: =(C14*Assumptions!$G$41+C15*Assumptions!$G$42+C16*Assumptions!$G$43+C17*Assumptions!$G$44+C18*Assumptions!$G$45+C19*Assumptions!$G$46+C20*Assumptions!$G$47)*Assumptions!B$58 -> 43024 | D37: =(D14*Assumptions!$G$41+D15*Assumptions!$G$42+D16*Assumptions!$G$43+D17*Assumptions!$G$44+D18*Assumptions!$G$45+D19*Assumptions!$G$46+D20*Assumptions!$G$47)*Assumptions!C$58 -> 158928 | E37: =(E14*Assumptions!$G$41+E15*Assumptions!$G$42+E16*Assumptions!$G$43+E17*Assumptions!$G$44+E18*Assumptions!$G$45+E19*Assumptions!$G$46+E20*Assumptions!$G$47)*Assumptions!D$58 -> 874337.5 | F37: =(F14*Assumptions!$G$41+F15*Assumptions!$G$42+F16*Assumptions!$G$43+F17*Assumptions!$G$44+F18*Assumptions!$G$45+F19*Assumptions!$G$46+F20*Assumptions!$G$47)*Assumptions!E$58 -> 4256910
A38: Programmatic ad revenue | C38: =(C14*Assumptions!$G$41*Assumptions!$F$41+C15*Assumptions!$G$42*Assumptions!$F$42+C16*Assumptions!$G$43*Assumptions!$F$43+C17*Assumptions!$G$44*Assumptions!$F$44+C18*Assumptions!$G$45*Assumptions!$F$45+C19*Assumptions!$G$46*Assumptions!$F$46+C20*Assumptions!$G$47*Assumptions!$F$47)*Assumptions!B$58/1000*INDEX(Assumptions!$B$73:$D$73,Assumptions!$B$5)*INDEX(Assumptions!$B$74:$D$74,Assumptions!$B$5)*INDEX(Assumptions!$B$75:$D$75,Assumptions!$B$5) -> 453.3732 | D38: =(D14*Assumptions!$G$41*Assumptions!$F$41+D15*Assumptions!$G$42*Assumptions!$F$42+D16*Assumptions!$G$43*Assumptions!$F$43+D17*Assumptions!$G$44*Assumptions!$F$44+D18*Assumptions!$G$45*Assumptions!$F$45+D19*Assumptions!$G$46*Assumptions!$F$46+D20*Assumptions!$G$47*Assumptions!$F$47)*Assumptions!C$58/1000*INDEX(Assumptions!$B$73:$D$73,Assumptions!$B$5)*INDEX(Assumptions!$B$74:$D$74,Assumptions!$B$5)*INDEX(Assumptions!$B$75:$D$75,Assumptions!$B$5) -> 1653.3234 | E38: =(E14*Assumptions!$G$41*Assumptions!$F$41+E15*Assumptions!$G$42*Assumptions!$F$42+E16*Assumptions!$G$43*Assumptions!$F$43+E17*Assumptions!$G$44*Assumptions!$F$44+E18*Assumptions!$G$45*Assumptions!$F$45+E19*Assumptions!$G$46*Assumptions!$F$46+E20*Assumptions!$G$47*Assumptions!$F$47)*Assumptions!D$58/1000*INDEX(Assumptions!$B$73:$D$73,Assumptions!$B$5)*INDEX(Assumptions!$B$74:$D$74,Assumptions!$B$5)*INDEX(Assumptions!$B$75:$D$75,Assumptions!$B$5) -> 9312.165 | F38: =(F14*Assumptions!$G$41*Assumptions!$F$41+F15*Assumptions!$G$42*Assumptions!$F$42+F16*Assumptions!$G$43*Assumptions!$F$43+F17*Assumptions!$G$44*Assumptions!$F$44+F18*Assumptions!$G$45*Assumptions!$F$45+F19*Assumptions!$G$46*Assumptions!$F$46+F20*Assumptions!$G$47*Assumptions!$F$47)*Assumptions!E$58/1000*INDEX(Assumptions!$B$73:$D$73,Assumptions!$B$5)*INDEX(Assumptions!$B$74:$D$74,Assumptions!$B$5)*INDEX(Assumptions!$B$75:$D$75,Assumptions!$B$5) -> 44323.524
A39: Local sponsors (local + courts shows) | C39: =(C5+C7)*Assumptions!B$85*INDEX(Assumptions!$B$76:$D$76,Assumptions!$B$5) -> 562.5 | D39: =(D5+D7)*Assumptions!C$85*INDEX(Assumptions!$B$76:$D$76,Assumptions!$B$5) -> 3375 | E39: =(E5+E7)*Assumptions!D$85*INDEX(Assumptions!$B$76:$D$76,Assumptions!$B$5) -> 26250 | F39: =(F5+F7)*Assumptions!E$85*INDEX(Assumptions!$B$76:$D$76,Assumptions!$B$5) -> 146250
A40: B2B white-label briefs | C40: =Assumptions!B$86*INDEX(Assumptions!$B$77:$D$77,Assumptions!$B$5) -> 0 | D40: =Assumptions!C$86*INDEX(Assumptions!$B$77:$D$77,Assumptions!$B$5) -> 2000 | E40: =Assumptions!D$86*INDEX(Assumptions!$B$77:$D$77,Assumptions!$B$5) -> 10000 | F40: =Assumptions!E$86*INDEX(Assumptions!$B$77:$D$77,Assumptions!$B$5) -> 40000
A41: Trust Stack API | C41: =Assumptions!B$87*INDEX(Assumptions!$B$78:$D$78,Assumptions!$B$5) -> 0 | D41: =Assumptions!C$87*INDEX(Assumptions!$B$78:$D$78,Assumptions!$B$5) -> 0 | E41: =Assumptions!D$87*INDEX(Assumptions!$B$78:$D$78,Assumptions!$B$5) -> 4500 | F41: =Assumptions!E$87*INDEX(Assumptions!$B$78:$D$78,Assumptions!$B$5) -> 22500
A42: C&C Studio Services | C42: =Assumptions!B$88*INDEX(Assumptions!$B$79:$D$79,Assumptions!$B$5) -> 3000 | D42: =Assumptions!C$88*INDEX(Assumptions!$B$79:$D$79,Assumptions!$B$5) -> 6000 | E42: =Assumptions!D$88*INDEX(Assumptions!$B$79:$D$79,Assumptions!$B$5) -> 9000 | F42: =Assumptions!E$88*INDEX(Assumptions!$B$79:$D$79,Assumptions!$B$5) -> 12000
A43: Premium subscriptions | C43: =Assumptions!B$89*INDEX(Assumptions!$B$80:$D$80,Assumptions!$B$5)*Assumptions!$B$81 -> 0 | D43: =Assumptions!C$89*INDEX(Assumptions!$B$80:$D$80,Assumptions!$B$5)*Assumptions!$B$81 -> 175 | E43: =Assumptions!D$89*INDEX(Assumptions!$B$80:$D$80,Assumptions!$B$5)*Assumptions!$B$81 -> 1750 | F43: =Assumptions!E$89*INDEX(Assumptions!$B$80:$D$80,Assumptions!$B$5)*Assumptions!$B$81 -> 10500
...

Sheet Cost Lines
A1: Cost-out — every cost line by scenario (monthly unless one-time)
A2: Variable lines link to Scenarios; fixed lines = unit cost × quantity. Edit blue cells.
A4: Category | B4: Item | C4: Vendor / plan | D4: Type | E4: Unit cost $/mo | F4: Qty: Test | G4: Qty: Wave 1 | H4: Qty: Scale | I4: Qty: Dominate | J4: $/mo Test | K4: $/mo Wave 1 | L4: $/mo Scale | M4: $/mo Dominate
A5: Variable | B5: Claude API — agents + web search | C5: usage-based | D5: variable | J5: =Scenarios!C31 -> 264.08055 | K5: =Scenarios!D31 -> 813.63734 | L5: =Scenarios!E31 -> 3688.3931 | M5: =Scenarios!F31 -> 14863.476 | N5: From Scenarios (episodes × per-episode cost)
A6: Variable | B6: ElevenLabs voice | C6: usage-based | D6: variable | J6: =Scenarios!C29 -> 189.33 | K6: =Scenarios!D29 -> 990 | L6: =Scenarios!E29 -> 3000 | M6: =Scenarios!F29 -> 5116.776 | N6: From Scenarios (episodes × per-episode cost)
A7: Hosting | B7: Podcast hosting + dynamic ad insertion | C7: Multi-show host (see cost-analysis.md) | D7: monthly | E7: 49 | F7: 1 | G7: 2 | H7: 4 | I7: 10 | J7: =$E7*F7 -> 49 | K7: =$E7*G7 -> 98 | L7: =$E7*H7 -> 196 | M7: =$E7*I7 -> 490 | N7: Plan tiers scale with downloads/shows (F-HOST) — verify
A8: Insurance | B8: Media liability / E&O | C8: Online insurer quote | D8: monthly | E8: 78 | F8: 1 | G8: 1 | H8: 2 | I8: 3 | J8: =$E8*F8 -> 78 | K8: =$E8*G8 -> 78 | L8: =$E8*H8 -> 156 | M8: =$E8*I8 -> 234 | N8: Insureon avg ~$78/mo; larger limits at scale (F-LEGAL)
A9: Infrastructure | B9: GitHub (Actions minutes, private repos) | C9: GitHub Free → Team | D9: monthly | E9: 0 | F9: 1 | G9: 1 | H9: 1 | I9: 1 | J9: =$E9*F9 -> 0 | K9: =$E9*G9 -> 0 | L9: =$E9*H9 -> 0 | M9: =$E9*I9 -> 0 | N9: Public repo Actions are free; Team $4/user if needed
A10: Infrastructure | B10: Database (Supabase) | C10: Free → Pro | D10: monthly | E10: 0 | F10: 1 | G10: 1 | H10: 1 | I10: 1 | J10: =$E10*F10 -> 0 | K10: =$E10*G10 -> 0 | L10: =$E10*H10 -> 0 | M10: =$E10*I10 -> 0 | N10: Free tier at test; set to 25 for Pro
A11: Infrastructure | B11: Compute for always-on agents / runners | C11: VPS or managed runners | D11: monthly | E11: 0 | F11: 0 | G11: 20 | H11: 150 | I11: 800 | J11: =$E11*F11 -> 0 | K11: =$E11*G11 -> 0 | L11: =$E11*H11 -> 0 | M11: =$E11*I11 -> 0 | N11: (inference) GitHub Actions covers early stages
A12: Data | B12: News/search data APIs beyond RSS | C12: e.g. news API, court data | D12: monthly | E12: 0 | F12: 0 | G12: 100 | H12: 500 | I12: 2000 | J12: =$E12*F12 -> 0 | K12: =$E12*G12 -> 0 | L12: =$E12*H12 -> 0 | M12: =$E12*I12 -> 0 | N12: (inference) RSS, GDELT, CourtListener free tiers first (F-DATA)
A13: Voice | B13: Google AI Pro (NotebookLM, optional) | C13: Google AI Pro | D13: monthly | E13: 19.99 | F13: 1 | G13: 1 | H13: 0 | I13: 0 | J13: =$E13*F13 -> 19.99 | K13: =$E13*G13 -> 19.99 | L13: =$E13*H13 -> 0 | M13: =$E13*I13 -> 0 | N13: Optional; prototyping only (F-TTS)
A14: Admin | B14: Domain + email | C14: Registrar + mailbox | D14: monthly | E14: 8 | F14: 1 | G14: 1 | H14: 1 | I14: 1 | J14: =$E14*F14 -> 8 | K14: =$E14*G14 -> 8 | L14: =$E14*H14 -> 8 | M14: =$E14*I14 -> 8 | N14: (inference)
A15: Admin | B15: Bookkeeping software | C15: e.g. QuickBooks/Wave | D15: monthly | E15: 30 | F15: 1 | G15: 1 | H15: 1 | I15: 1 | J15: =$E15*F15 -> 30 | K15: =$E15*G15 -> 30 | L15: =$E15*H15 -> 30 | M15: =$E15*I15 -> 30 | N15: (inference)
A16: Admin | B16: Design tools (cover art, clips) | C16: Canva Pro or similar | D16: monthly | E16: 15 | F16: 1 | G16: 1 | H16: 1 | I16: 2 | J16: =$E16*F16 -> 15 | K16: =$E16*G16 -> 15 | L16: =$E16*H16 -> 15 | M16: =$E16*I16 -> 30 | N16: (inference)
A17: People | B17: Contract help (sales, legal on retainer) | C17: Freelance | D17: monthly | E17: 0 | F17: 0 | G17: 0 | H17: 2000 | I17: 8000 | J17: =$E17*F17 -> 0 | K17: =$E17*G17 -> 0 | L17: =$E17*H17 -> 0 | M17: =$E17*I17 -> 0 | N17: (inference) first hires come from revenue
B18: Fixed operating subtotal | J18: =SUM(J7:J17) -> 199.99 | K18: =SUM(K7:K17) -> 248.99 | L18: =SUM(L7:L17) -> 405 | M18: =SUM(M7:M17) -> 792
B19: TOTAL MONTHLY (variable + fixed) | J19: =SUM(J5:J6)+J18 -> 653.40055 | K19: =SUM(K5:K6)+K18 -> 2052.6273 | L19: =SUM(L5:L6)+L18 -> 7093.3931 | M19: =SUM(M5:M6)+M18 -> 20772.252
A21: One-time startup costs
A22: Category | B22: Item | E22: Cost $ | M22: Note / source
A23: Legal | B23: Media-lawyer consult on standards + courts/crime lanes | E23: 1500 | M23: (inference) 3–5 hrs
A24: Legal | B24: Trademark: 'Curious & Creative Network' (2 classes) | E24: 700 | M24: USPTO $350/class (F-LEGAL)
A25: Legal | B25: DBA / assumed-name filing | E25: 50 | M25: Varies by state/county (F-LEGAL)
A26: Brand | B26: Network + show cover art and sonic logo | E26: 500 | M26: (inference)
A27: Admin | B27: Domain registration (year 1) | E27: 20 | M27: (inference)
A28: Voice | B28: Voice design / pronunciation dictionaries setup | E28: 0 | M28: Included in ElevenLabs plan
B29: Total one-time | E29: =SUM(E23:E28) -> 2770

Sheet 12-Month Plan
A1: 12-month cash curve and payback
A2: Stage and audience ramp per month are set on Assumptions.
A4: Month | B4: Stage | C4: Audience ramp | D4: Operating cost | E4: One-time cost | F4: Ad revenue | G4: Other revenue | H4: Total revenue | I4: Net | J4: Cumulative cash | K4: Payback flag | L4: Network-only net | M4: Network-only cumulative
A5: 1 | B5: =Assumptions!B$93 -> 1 | C5: =Assumptions!B$94 -> 0.1 | D5: =INDEX(Scenarios!$C$33:$F$33,B5) -> 653.40055 | E5: ='Cost Lines'!$E$29 -> 2770 | F5: =INDEX(Scenarios!$C$38:$F$38,B5)*C5 -> 45.33732 | G5: =(INDEX(Scenarios!$C$44:$F$44,B5)-INDEX(Scenarios!$C$38:$F$38,B5))*C5 -> 356.25 | H5: =F5+G5 -> 401.58732 | I5: =H5-D5-E5 -> -3021.8132 | J5: =I5 -> -3021.8132 | K5: =IF(J5>=0,IF(TRUE(),A5,""),"") | L5: =INDEX(Scenarios!$C$49:$F$49,B5)*C5-D5-E5 -> -3321.8132 | M5: =L5 -> -3321.8132
A6: 2 | B6: =Assumptions!C$93 -> 1 | C6: =Assumptions!C$94 -> 0.2 | D6: =INDEX(Scenarios!$C$33:$F$33,B6) -> 653.40055 | E6: =0 -> 0 | F6: =INDEX(Scenarios!$C$38:$F$38,B6)*C6 -> 90.67464 | G6: =(INDEX(Scenarios!$C$44:$F$44,B6)-INDEX(Scenarios!$C$38:$F$38,B6))*C6 -> 712.5 | H6: =F6+G6 -> 803.17464 | I6: =H6-D6-E6 -> 149.77409 | J6: =J5+I6 -> -2872.0391 | K6: =IF(J6>=0,IF(J5<0,A6,""),"") | L6: =INDEX(Scenarios!$C$49:$F$49,B6)*C6-D6-E6 -> -450.22591 | M6: =M5+L6 -> -3772.0391
A7: 3 | B7: =Assumptions!D$93 -> 1 | C7: =Assumptions!D$94 -> 0.3 | D7: =INDEX(Scenarios!$C$33:$F$33,B7) -> 653.40055 | E7: =0 -> 0 | F7: =INDEX(Scenarios!$C$38:$F$38,B7)*C7 -> 136.01196 | G7: =(INDEX(Scenarios!$C$44:$F$44,B7)-INDEX(Scenarios!$C$38:$F$38,B7))*C7 -> 1068.75 | H7: =F7+G7 -> 1204.762 | I7: =H7-D7-E7 -> 551.36141 | J7: =J6+I7 -> -2320.6777 | K7: =IF(J7>=0,IF(J6<0,A7,""),"") | L7: =INDEX(Scenarios!$C$49:$F$49,B7)*C7-D7-E7 -> -348.63859 | M7: =M6+L7 -> -4120.6777
A8: 4 | B8: =Assumptions!E$93 -> 2 | C8: =Assumptions!E$94 -> 0.35 | D8: =INDEX(Scenarios!$C$33:$F$33,B8) -> 2052.6273 | E8: =0 -> 0 | F8: =INDEX(Scenarios!$C$38:$F$38,B8)*C8 -> 578.66319 | G8: =(INDEX(Scenarios!$C$44:$F$44,B8)-INDEX(Scenarios!$C$38:$F$38,B8))*C8 -> 4042.5 | H8: =F8+G8 -> 4621.1632 | I8: =H8-D8-E8 -> 2568.5358 | J8: =J7+I8 -> 247.85812 | K8: =IF(J8>=0,IF(J7<0,A8,""),"") -> 4 | L8: =INDEX(Scenarios!$C$49:$F$49,B8)*C8-D8-E8 -> -231.46415 | M8: =M7+L8 -> -4352.1419
A9: 5 | B9: =Assumptions!F$93 -> 2 | C9: =Assumptions!F$94 -> 0.45 | D9: =INDEX(Scenarios!$C$33:$F$33,B9) -> 2052.6273 | E9: =0 -> 0 | F9: =INDEX(Scenarios!$C$38:$F$38,B9)*C9 -> 743.99553 | G9: =(INDEX(Scenarios!$C$44:$F$44,B9)-INDEX(Scenarios!$C$38:$F$38,B9))*C9 -> 5197.5 | H9: =F9+G9 -> 5941.4955 | I9: =H9-D9-E9 -> 3888.8682 | J9: =J8+I9 -> 4136.7263 | K9: =IF(J9>=0,IF(J8<0,A9,""),"") | L9: =INDEX(Scenarios!$C$49:$F$49,B9)*C9-D9-E9 -> 288.86819 | M9: =M8+L9 -> -4063.2737
A10: 6 | B10: =Assumptions!G$93 -> 2 | C10: =Assumptions!G$94 -> 0.55 | D10: =INDEX(Scenarios!$C$33:$F$33,B10) -> 2052.6273 | E10: =0 -> 0 | F10: =INDEX(Scenarios!$C$38:$F$38,B10)*C10 -> 909.32787 | G10: =(INDEX(Scenarios!$C$44:$F$44,B10)-INDEX(Scenarios!$C$38:$F$38,B10))*C10 -> 6352.5 | H10: =F10+G10 -> 7261.8279 | I10: =H10-D10-E10 -> 5209.2005 | J10: =J9+I10 -> 9345.9268 | K10: =IF(J10>=0,IF(J9<0,A10,""),"") | L10: =INDEX(Scenarios!$C$49:$F$49,B10)*C10-D10-E10 -> 809.20053 | M10: =M9+L10 -> -3254.0732
A11: 7 | B11: =Assumptions!H$93 -> 3 | C11: =Assumptions!H$94 -> 0.5 | D11: =INDEX(Scenarios!$C$33:$F$33,B11) -> 7093.3931 | E11: =0 -> 0 | F11: =INDEX(Scenarios!$C$38:$F$38,B11)*C11 -> 4656.0825 | G11: =(INDEX(Scenarios!$C$44:$F$44,B11)-INDEX(Scenarios!$C$38:$F$38,B11))*C11 -> 25750 | H11: =F11+G11 -> 30406.083 | I11: =H11-D11-E11 -> 23312.689 | J11: =J10+I11 -> 32658.616 | K11: =IF(J11>=0,IF(J10<0,A11,""),"") | L11: =INDEX(Scenarios!$C$49:$F$49,B11)*C11-D11-E11 -> 11562.689 | M11: =M10+L11 -> 8308.6162
A12: 8 | B12: =Assumptions!I$93 -> 3 | C12: =Assumptions!I$94 -> 0.6 | D12: =INDEX(Scenarios!$C$33:$F$33,B12) -> 7093.3931 | E12: =0 -> 0 | F12: =INDEX(Scenarios!$C$38:$F$38,B12)*C12 -> 5587.299 | G12: =(INDEX(Scenarios!$C$44:$F$44,B12)-INDEX(Scenarios!$C$38:$F$38,B12))*C12 -> 30900 | H12: =F12+G12 -> 36487.299 | I12: =H12-D12-E12 -> 29393.906 | J12: =J11+I12 -> 62052.522 | K12: =IF(J12>=0,IF(J11<0,A12,""),"") | L12: =INDEX(Scenarios!$C$49:$F$49,B12)*C12-D12-E12 -> 15293.906 | M12: =M11+L12 -> 23602.522
A13: 9 | B13: =Assumptions!J$93 -> 3 | C13: =Assumptions!J$94 -> 0.7 | D13: =INDEX(Scenarios!$C$33:$F$33,B13) -> 7093.3931 | E13: =0 -> 0 | F13: =INDEX(Scenarios!$C$38:$F$38,B13)*C13 -> 6518.5155 | G13: =(INDEX(Scenarios!$C$44:$F$44,B13)-INDEX(Scenarios!$C$38:$F$38,B13))*C13 -> 36050 | H13: =F13+G13 -> 42568.516 | I13: =H13-D13-E13 -> 35475.122 | J13: =J12+I13 -> 97527.644 | K13: =IF(J13>=0,IF(J12<0,A13,""),"") | L13: =INDEX(Scenarios!$C$49:$F$49,B13)*C13-D13-E13 -> 19025.122 | M13: =M12+L13 -> 42627.644
A14: 10 | B14: =Assumptions!K$93 -> 3 | C14: =Assumptions!K$94 -> 0.8 | D14: =INDEX(Scenarios!$C$33:$F$33,B14) -> 7093.3931 | E14: =0 -> 0 | F14: =INDEX(Scenarios!$C$38:$F$38,B14)*C14 -> 7449.732 | G14: =(INDEX(Scenarios!$C$44:$F$44,B14)-INDEX(Scenarios!$C$38:$F$38,B14))*C14 -> 41200 | H14: =F14+G14 -> 48649.732 | I14: =H14-D14-E14 -> 41556.339 | J14: =J13+I14 -> 139083.98 | K14: =IF(J14>=0,IF(J13<0,A14,""),"") | L14: =INDEX(Scenarios!$C$49:$F$49,B14)*C14-D14-E14 -> 22756.339 | M14: =M13+L14 -> 65383.983
A15: 11 | B15: =Assumptions!L$93 -> 3 | C15: =Assumptions!L$94 -> 0.9 | D15: =INDEX(Scenarios!$C$33:$F$33,B15) -> 7093.3931 | E15: =0 -> 0 | F15: =INDEX(Scenarios!$C$38:$F$38,B15)*C15 -> 8380.9485 | G15: =(INDEX(Scenarios!$C$44:$F$44,B15)-INDEX(Scenarios!$C$38:$F$38,B15))*C15 -> 46350 | H15: =F15+G15 -> 54730.948 | I15: =H15-D15-E15 -> 47637.555 | J15: =J14+I15 -> 186721.54 | K15: =IF(J15>=0,IF(J14<0,A15,""),"") | L15: =INDEX(Scenarios!$C$49:$F$49,B15)*C15-D15-E15 -> 26487.555 | M15: =M14+L15 -> 91871.539
A16: 12 | B16: =Assumptions!M$93 -> 3 | C16: =Assumptions!M$94 -> 1 | D16: =INDEX(Scenarios!$C$33:$F$33,B16) -> 7093.3931 | E16: =0 -> 0 | F16: =INDEX(Scenarios!$C$38:$F$38,B16)*C16 -> 9312.165 | G16: =(INDEX(Scenarios!$C$44:$F$44,B16)-INDEX(Scenarios!$C$38:$F$38,B16))*C16 -> 51500 | H16: =F16+G16 -> 60812.165 | I16: =H16-D16-E16 -> 53718.772 | J16: =J15+I16 -> 240440.31 | K16: =IF(J16>=0,IF(J15<0,A16,""),"") | L16: =INDEX(Scenarios!$C$49:$F$49,B16)*C16-D16-E16 -> 30218.772 | M16: =M15+L16 -> 122090.31
A18: Every show in a stage publishes from its first month, so operating cost is charged in full; only revenue follows the audience ramp (conservative on purpose).
A20: Payback month | D20: =IF(COUNT(K5:K16)=0,"Not within 12 months",MIN(K5:K16)) -> 4
A21: Lowest cash point (max investment needed) | D21: =MIN(0,MIN(J5:J16)) -> -3021.8132
A22: Year-1 revenue | D22: =SUM(H5:H16) -> 293888.75
A23: Year-1 total cost | D23: =SUM(D5:D16)+SUM(E5:E16) -> 53448.442
A24: Year-1 ROI (net ÷ total cost) | D24: =IF(D23=0,0,(D22-D23)/D23) -> 4.4985466
A25: Network-only: lowest cash point | D25: =MIN(0,MIN(M5:M16)) -> -4352.1419
A26: Network-only: year-1 cumulative net | D26: =M16 -> 122090.31

Sheet Sensitivity
A1: Sensitivity — monthly net at the Scale scenario
A2: Rows: gross programmatic CPM. Columns: average downloads per episode across the network. Other revenue and all costs held at the Scale scenario.
A4: CPM ↓ / downloads per episode → | B4: 25 | C4: 50 | D4: 100 | E4: 250 | F4: 500 | G4: 1000 | H4: 2500
A5: 5 | B5: =Scenarios!$E$21*B$4*(SUMPRODUCT(Scenarios!E14:E20,Assumptions!$F$41:$F$47)/MAX(1,Scenarios!E21))/1000*$A5*INDEX(Assumptions!$B$74:$D$74,Assumptions!$B$5)*INDEX(Assumptions!$B$75:$D$75,Assumptions!$B$5)+(Scenarios!E44-Scenarios!E38)-Scenarios!$E$33 -> 44563.927 | C5: =Scenarios!$E$21*C$4*(SUMPRODUCT(Scenarios!E14:E20,Assumptions!$F$41:$F$47)/MAX(1,Scenarios!E21))/1000*$A5*INDEX(Assumptions!$B$74:$D$74,Assumptions!$B$5)*INDEX(Assumptions!$B$75:$D$75,Assumptions!$B$5)+(Scenarios!E44-Scenarios!E38)-Scenarios!$E$33 -> 44721.247 | D5: =Scenarios!$E$21*D$4*(SUMPRODUCT(Scenarios!E14:E20,Assumptions!$F$41:$F$47)/MAX(1,Scenarios!E21))/1000*$A5*INDEX(Assumptions!$B$74:$D$74,Assumptions!$B$5)*INDEX(Assumptions!$B$75:$D$75,Assumptions!$B$5)+(Scenarios!E44-Scenarios!E38)-Scenarios!$E$33 -> 45035.887 | E5: =Scenarios!$E$21*E$4*(SUMPRODUCT(Scenarios!E14:E20,Assumptions!$F$41:$F$47)/MAX(1,Scenarios!E21))/1000*$A5*INDEX(Assumptions!$B$74:$D$74,Assumptions!$B$5)*INDEX(Assumptions!$B$75:$D$75,Assumptions!$B$5)+(Scenarios!E44-Scenarios!E38)-Scenarios!$E$33 -> 45979.807 | F5: =Scenarios!$E$21*F$4*(SUMPRODUCT(Scenarios!E14:E20,Assumptions!$F$41:$F$47)/MAX(1,Scenarios!E21))/1000*$A5*INDEX(Assumptions!$B$74:$D$74,Assumptions!$B$5)*INDEX(Assumptions!$B$75:$D$75,Assumptions!$B$5)+(Scenarios!E44-Scenarios!E38)-Scenarios!$E$33 -> 47553.007 | G5: =Scenarios!$E$21*G$4*(SUMPRODUCT(Scenarios!E14:E20,Assumptions!$F$41:$F$47)/MAX(1,Scenarios!E21))/1000*$A5*INDEX(Assumptions!$B$74:$D$74,Assumptions!$B$5)*INDEX(Assumptions!$B$75:$D$75,Assumptions!$B$5)+(Scenarios!E44-Scenarios!E38)-Scenarios!$E$33 -> 50699.407 | H5: =Scenarios!$E$21*H$4*(SUMPRODUCT(Scenarios!E14:E20,Assumptions!$F$41:$F$47)/MAX(1,Scenarios!E21))/1000*$A5*INDEX(Assumptions!$B$74:$D$74,Assumptions!$B$5)*INDEX(Assumptions!$B$75:$D$75,Assumptions!$B$5)+(Scenarios!E44-Scenarios!E38)-Scenarios!$E$33 -> 60138.607
A6: 8 | B6: =Scenarios!$E$21*B$4*(SUMPRODUCT(Scenarios!E14:E20,Assumptions!$F$41:$F$47)/MAX(1,Scenarios!E21))/1000*$A6*INDEX(Assumptions!$B$74:$D$74,Assumptions!$B$5)*INDEX(Assumptions!$B$75:$D$75,Assumptions!$B$5)+(Scenarios!E44-Scenarios!E38)-Scenarios!$E$33 -> 44658.319 | C6: =Scenarios!$E$21*C$4*(SUMPRODUCT(Scenarios!E14:E20,Assumptions!$F$41:$F$47)/MAX(1,Scenarios!E21))/1000*$A6*INDEX(Assumptions!$B$74:$D$74,Assumptions!$B$5)*INDEX(Assumptions!$B$75:$D$75,Assumptions!$B$5)+(Scenarios!E44-Scenarios!E38)-Scenarios!$E$33 -> 44910.031 | D6: =Scenarios!$E$21*D$4*(SUMPRODUCT(Scenarios!E14:E20,Assumptions!$F$41:$F$47)/MAX(1,Scenarios!E21))/1000*$A6*INDEX(Assumptions!$B$74:$D$74,Assumptions!$B$5)*INDEX(Assumptions!$B$75:$D$75,Assumptions!$B$5)+(Scenarios!E44-Scenarios!E38)-Scenarios!$E$33 -> 45413.455 | E6: =Scenarios!$E$21*E$4*(SUMPRODUCT(Scenarios!E14:E20,Assumptions!$F$41:$F$47)/MAX(1,Scenarios!E21))/1000*$A6*INDEX(Assumptions!$B$74:$D$74,Assumptions!$B$5)*INDEX(Assumptions!$B$75:$D$75,Assumptions!$B$5)+(Scenarios!E44-Scenarios!E38)-Scenarios!$E$33 -> 46923.727 | F6: =Scenarios!$E$21*F$4*(SUMPRODUCT(Scenarios!E14:E20,Assumptions!$F$41:$F$47)/MAX(1,Scenarios!E21))/1000*$A6*INDEX(Assumptions!$B$74:$D$74,Assumptions!$B$5)*INDEX(Assumptions!$B$75:$D$75,Assumptions!$B$5)+(Scenarios!E44-Scenarios!E38)-Scenarios!$E$33 -> 49440.847 | G6: =Scenarios!$E$21*G$4*(SUMPRODUCT(Scenarios!E14:E20,Assumptions!$F$41:$F$47)/MAX(1,Scenarios!E21))/1000*$A6*INDEX(Assumptions!$B$74:$D$74,Assumptions!$B$5)*INDEX(Assumptions!$B$75:$D$75,Assumptions!$B$5)+(Scenarios!E44-Scenarios!E38)-Scenarios!$E$33 -> 54475.087 | H6: =Scenarios!$E$21*H$4*(SUMPRODUCT(Scenarios!E14:E20,Assumptions!$F$41:$F$47)/MAX(1,Scenarios!E21))/1000*$A6*INDEX(Assumptions!$B$74:$D$74,Assumptions!$B$5)*INDEX(Assumptions!$B$75:$D$75,Assumptions!$B$5)+(Scenarios!E44-Scenarios!E38)-Scenarios!$E$33 -> 69577.807
A7: 10 | B7: =Scenarios!$E$21*B$4*(SUMPRODUCT(Scenarios!E14:E20,Assumptions!$F$41:$F$47)/MAX(1,Scenarios!E21))/1000*$A7*INDEX(Assumptions!$B$74:$D$74,Assumptions!$B$5)*INDEX(Assumptions!$B$75:$D$75,Assumptions!$B$5)+(Scenarios!E44-Scenarios!E38)-Scenarios!$E$33 -> 44721.247 | C7: =Scenarios!$E$21*C$4*(SUMPRODUCT(Scenarios!E14:E20,Assumptions!$F$41:$F$47)/MAX(1,Scenarios!E21))/1000*$A7*INDEX(Assumptions!$B$74:$D$74,Assumptions!$B$5)*INDEX(Assumptions!$B$75:$D$75,Assumptions!$B$5)+(Scenarios!E44-Scenarios!E38)-Scenarios!$E$33 -> 45035.887 | D7: =Scenarios!$E$21*D$4*(SUMPRODUCT(Scenarios!E14:E20,Assumptions!$F$41:$F$47)/MAX(1,Scenarios!E21))/1000*$A7*INDEX(Assumptions!$B$74:$D$74,Assumptions!$B$5)*INDEX(Assumptions!$B$75:$D$75,Assumptions!$B$5)+(Scenarios!E44-Scenarios!E38)-Scenarios!$E$33 -> 45665.167 | E7: =Scenarios!$E$21*E$4*(SUMPRODUCT(Scenarios!E14:E20,Assumptions!$F$41:$F$47)/MAX(1,Scenarios!E21))/1000*$A7*INDEX(Assumptions!$B$74:$D$74,Assumptions!$B$5)*INDEX(Assumptions!$B$75:$D$75,Assumptions!$B$5)+(Scenarios!E44-Scenarios!E38)-Scenarios!$E$33 -> 47553.007 | F7: =Scenarios!$E$21*F$4*(SUMPRODUCT(Scenarios!E14:E20,Assumptions!$F$41:$F$47)/MAX(1,Scenarios!E21))/1000*$A7*INDEX(Assumptions!$B$74:$D$74,Assumptions!$B$5)*INDEX(Assumptions!$B$75:$D$75,Assumptions!$B$5)+(Scenarios!E44-Scenarios!E38)-Scenarios!$E$33 -> 50699.407 | G7: =Scenarios!$E$21*G$4*(SUMPRODUCT(Scenarios!E14:E20,Assumptions!$F$41:$F$47)/MAX(1,Scenarios!E21))/1000*$A7*INDEX(Assumptions!$B$74:$D$74,Assumptions!$B$5)*INDEX(Assumptions!$B$75:$D$75,Assumptions!$B$5)+(Scenarios!E44-Scenarios!E38)-Scenarios!$E$33 -> 56992.207 | H7: =Scenarios!$E$21*H$4*(SUMPRODUCT(Scenarios!E14:E20,Assumptions!$F$41:$F$47)/MAX(1,Scenarios!E21))/1000*$A7*INDEX(Assumptions!$B$74:$D$74,Assumptions!$B$5)*INDEX(Assumptions!$B$75:$D$75,Assumptions!$B$5)+(Scenarios!E44-Scenarios!E38)-Scenarios!$E$33 -> 75870.607
A8: 15 | B8: =Scenarios!$E$21*B$4*(SUMPRODUCT(Scenarios!E14:E20,Assumptions!$F$41:$F$47)/MAX(1,Scenarios!E21))/1000*$A8*INDEX(Assumptions!$B$74:$D$74,Assumptions!$B$5)*INDEX(Assumptions!$B$75:$D$75,Assumptions!$B$5)+(Scenarios!E44-Scenarios!E38)-Scenarios!$E$33 -> 44878.567 | C8: =Scenarios!$E$21*C$4*(SUMPRODUCT(Scenarios!E14:E20,Assumptions!$F$41:$F$47)/MAX(1,Scenarios!E21))/1000*$A8*INDEX(Assumptions!$B$74:$D$74,Assumptions!$B$5)*INDEX(Assumptions!$B$75:$D$75,Assumptions!$B$5)+(Scenarios!E44-Scenarios!E38)-Scenarios!$E$33 -> 45350.527 | D8: =Scenarios!$E$21*D$4*(SUMPRODUCT(Scenarios!E14:E20,Assumptions!$F$41:$F$47)/MAX(1,Scenarios!E21))/1000*$A8*INDEX(Assumptions!$B$74:$D$74,Assumptions!$B$5)*INDEX(Assumptions!$B$75:$D$75,Assumptions!$B$5)+(Scenarios!E44-Scenarios!E38)-Scenarios!$E$33 -> 46294.447 | E8: =Scenarios!$E$21*E$4*(SUMPRODUCT(Scenarios!E14:E20,Assumptions!$F$41:$F$47)/MAX(1,Scenarios!E21))/1000*$A8*INDEX(Assumptions!$B$74:$D$74,Assumptions!$B$5)*INDEX(Assumptions!$B$75:$D$75,Assumptions!$B$5)+(Scenarios!E44-Scenarios!E38)-Scenarios!$E$33 -> 49126.207 | F8: =Scenarios!$E$21*F$4*(SUMPRODUCT(Scenarios!E14:E20,Assumptions!$F$41:$F$47)/MAX(1,Scenarios!E21))/1000*$A8*INDEX(Assumptions!$B$74:$D$74,Assumptions!$B$5)*INDEX(Assumptions!$B$75:$D$75,Assumptions!$B$5)+(Scenarios!E44-Scenarios!E38)-Scenarios!$E$33 -> 53845.807 | G8: =Scenarios!$E$21*G$4*(SUMPRODUCT(Scenarios!E14:E20,Assumptions!$F$41:$F$47)/MAX(1,Scenarios!E21))/1000*$A8*INDEX(Assumptions!$B$74:$D$74,Assumptions!$B$5)*INDEX(Assumptions!$B$75:$D$75,Assumptions!$B$5)+(Scenarios!E44-Scenarios!E38)-Scenarios!$E$33 -> 63285.007 | H8: =Scenarios!$E$21*H$4*(SUMPRODUCT(Scenarios!E14:E20,Assumptions!$F$41:$F$47)/MAX(1,Scenarios!E21))/1000*$A8*INDEX(Assumptions!$B$74:$D$74,Assumptions!$B$5)*INDEX(Assumptions!$B$75:$D$75,Assumptions!$B$5)+(Scenarios!E44-Scenarios!E38)-Scenarios!$E$33 -> 91602.607
A9: 20 | B9: =Scenarios!$E$21*B$4*(SUMPRODUCT(Scenarios!E14:E20,Assumptions!$F$41:$F$47)/MAX(1,Scenarios!E21))/1000*$A9*INDEX(Assumptions!$B$74:$D$74,Assumptions!$B$5)*INDEX(Assumptions!$B$75:$D$75,Assumptions!$B$5)+(Scenarios!E44-Scenarios!E38)-Scenarios!$E$33 -> 45035.887 | C9: =Scenarios!$E$21*C$4*(SUMPRODUCT(Scenarios!E14:E20,Assumptions!$F$41:$F$47)/MAX(1,Scenarios!E21))/1000*$A9*INDEX(Assumptions!$B$74:$D$74,Assumptions!$B$5)*INDEX(Assumptions!$B$75:$D$75,Assumptions!$B$5)+(Scenarios!E44-Scenarios!E38)-Scenarios!$E$33 -> 45665.167 | D9: =Scenarios!$E$21*D$4*(SUMPRODUCT(Scenarios!E14:E20,Assumptions!$F$41:$F$47)/MAX(1,Scenarios!E21))/1000*$A9*INDEX(Assumptions!$B$74:$D$74,Assumptions!$B$5)*INDEX(Assumptions!$B$75:$D$75,Assumptions!$B$5)+(Scenarios!E44-Scenarios!E38)-Scenarios!$E$33 -> 46923.727 | E9: =Scenarios!$E$21*E$4*(SUMPRODUCT(Scenarios!E14:E20,Assumptions!$F$41:$F$47)/MAX(1,Scenarios!E21))/1000*$A9*INDEX(Assumptions!$B$74:$D$74,Assumptions!$B$5)*INDEX(Assumptions!$B$75:$D$75,Assumptions!$B$5)+(Scenarios!E44-Scenarios!E38)-Scenarios!$E$33 -> 50699.407 | F9: =Scenarios!$E$21*F$4*(SUMPRODUCT(Scenarios!E14:E20,Assumptions!$F$41:$F$47)/MAX(1,Scenarios!E21))/1000*$A9*INDEX(Assumptions!$B$74:$D$74,Assumptions!$B$5)*INDEX(Assumptions!$B$75:$D$75,Assumptions!$B$5)+(Scenarios!E44-Scenarios!E38)-Scenarios!$E$33 -> 56992.207 | G9: =Scenarios!$E$21*G$4*(SUMPRODUCT(Scenarios!E14:E20,Assumptions!$F$41:$F$47)/MAX(1,Scenarios!E21))/1000*$A9*INDEX(Assumptions!$B$74:$D$74,Assumptions!$B$5)*INDEX(Assumptions!$B$75:$D$75,Assumptions!$B$5)+(Scenarios!E44-Scenarios!E38)-Scenarios!$E$33 -> 69577.807 | H9: =Scenarios!$E$21*H$4*(SUMPRODUCT(Scenarios!E14:E20,Assumptions!$F$41:$F$47)/MAX(1,Scenarios!E21))/1000*$A9*INDEX(Assumptions!$B$74:$D$74,Assumptions!$B$5)*INDEX(Assumptions!$B$75:$D$75,Assumptions!$B$5)+(Scenarios!E44-Scenarios!E38)-Scenarios!$E$33 -> 107334.61
A10: 25 | B10: =Scenarios!$E$21*B$4*(SUMPRODUCT(Scenarios!E14:E20,Assumptions!$F$41:$F$47)/MAX(1,Scenarios!E21))/1000*$A10*INDEX(Assumptions!$B$74:$D$74,Assumptions!$B$5)*INDEX(Assumptions!$B$75:$D$75,Assumptions!$B$5)+(Scenarios!E44-Scenarios!E38)-Scenarios!$E$33 -> 45193.207 | C10: =Scenarios!$E$21*C$4*(SUMPRODUCT(Scenarios!E14:E20,Assumptions!$F$41:$F$47)/MAX(1,Scenarios!E21))/1000*$A10*INDEX(Assumptions!$B$74:$D$74,Assumptions!$B$5)*INDEX(Assumptions!$B$75:$D$75,Assumptions!$B$5)+(Scenarios!E44-Scenarios!E38)-Scenarios!$E$33 -> 45979.807 | D10: =Scenarios!$E$21*D$4*(SUMPRODUCT(Scenarios!E14:E20,Assumptions!$F$41:$F$47)/MAX(1,Scenarios!E21))/1000*$A10*INDEX(Assumptions!$B$74:$D$74,Assumptions!$B$5)*INDEX(Assumptions!$B$75:$D$75,Assumptions!$B$5)+(Scenarios!E44-Scenarios!E38)-Scenarios!$E$33 -> 47553.007 | E10: =Scenarios!$E$21*E$4*(SUMPRODUCT(Scenarios!E14:E20,Assumptions!$F$41:$F$47)/MAX(1,Scenarios!E21))/1000*$A10*INDEX(Assumptions!$B$74:$D$74,Assumptions!$B$5)*INDEX(Assumptions!$B$75:$D$75,Assumptions!$B$5)+(Scenarios!E44-Scenarios!E38)-Scenarios!$E$33 -> 52272.607 | F10: =Scenarios!$E$21*F$4*(SUMPRODUCT(Scenarios!E14:E20,Assumptions!$F$41:$F$47)/MAX(1,Scenarios!E21))/1000*$A10*INDEX(Assumptions!$B$74:$D$74,Assumptions!$B$5)*INDEX(Assumptions!$B$75:$D$75,Assumptions!$B$5)+(Scenarios!E44-Scenarios!E38)-Scenarios!$E$33 -> 60138.607 | G10: =Scenarios!$E$21*G$4*(SUMPRODUCT(Scenarios!E14:E20,Assumptions!$F$41:$F$47)/MAX(1,Scenarios!E21))/1000*$A10*INDEX(Assumptions!$B$74:$D$74,Assumptions!$B$5)*INDEX(Assumptions!$B$75:$D$75,Assumptions!$B$5)+(Scenarios!E44-Scenarios!E38)-Scenarios!$E$33 -> 75870.607 | H10: =Scenarios!$E$21*H$4*(SUMPRODUCT(Scenarios!E14:E20,Assumptions!$F$41:$F$47)/MAX(1,Scenarios!E21))/1000*$A10*INDEX(Assumptions!$B$74:$D$74,Assumptions!$B$5)*INDEX(Assumptions!$B$75:$D$75,Assumptions!$B$5)+(Scenarios!E44-Scenarios!E38)-Scenarios!$E$33 -> 123066.61
A11: 30 | B11: =Scenarios!$E$21*B$4*(SUMPRODUCT(Scenarios!E14:E20,Assumptions!$F$41:$F$47)/MAX(1,Scenarios!E21))/1000*$A11*INDEX(Assumptions!$B$74:$D$74,Assumptions!$B$5)*INDEX(Assumptions!$B$75:$D$75,Assumptions!$B$5)+(Scenarios!E44-Scenarios!E38)-Scenarios!$E$33 -> 45350.527 | C11: =Scenarios!$E$21*C$4*(SUMPRODUCT(Scenarios!E14:E20,Assumptions!$F$41:$F$47)/MAX(1,Scenarios!E21))/1000*$A11*INDEX(Assumptions!$B$74:$D$74,Assumptions!$B$5)*INDEX(Assumptions!$B$75:$D$75,Assumptions!$B$5)+(Scenarios!E44-Scenarios!E38)-Scenarios!$E$33 -> 46294.447 | D11: =Scenarios!$E$21*D$4*(SUMPRODUCT(Scenarios!E14:E20,Assumptions!$F$41:$F$47)/MAX(1,Scenarios!E21))/1000*$A11*INDEX(Assumptions!$B$74:$D$74,Assumptions!$B$5)*INDEX(Assumptions!$B$75:$D$75,Assumptions!$B$5)+(Scenarios!E44-Scenarios!E38)-Scenarios!$E$33 -> 48182.287 | E11: =Scenarios!$E$21*E$4*(SUMPRODUCT(Scenarios!E14:E20,Assumptions!$F$41:$F$47)/MAX(1,Scenarios!E21))/1000*$A11*INDEX(Assumptions!$B$74:$D$74,Assumptions!$B$5)*INDEX(Assumptions!$B$75:$D$75,Assumptions!$B$5)+(Scenarios!E44-Scenarios!E38)-Scenarios!$E$33 -> 53845.807 | F11: =Scenarios!$E$21*F$4*(SUMPRODUCT(Scenarios!E14:E20,Assumptions!$F$41:$F$47)/MAX(1,Scenarios!E21))/1000*$A11*INDEX(Assumptions!$B$74:$D$74,Assumptions!$B$5)*INDEX(Assumptions!$B$75:$D$75,Assumptions!$B$5)+(Scenarios!E44-Scenarios!E38)-Scenarios!$E$33 -> 63285.007 | G11: =Scenarios!$E$21*G$4*(SUMPRODUCT(Scenarios!E14:E20,Assumptions!$F$41:$F$47)/MAX(1,Scenarios!E21))/1000*$A11*INDEX(Assumptions!$B$74:$D$74,Assumptions!$B$5)*INDEX(Assumptions!$B$75:$D$75,Assumptions!$B$5)+(Scenarios!E44-Scenarios!E38)-Scenarios!$E$33 -> 82163.407 | H11: =Scenarios!$E$21*H$4*(SUMPRODUCT(Scenarios!E14:E20,Assumptions!$F$41:$F$47)/MAX(1,Scenarios!E21))/1000*$A11*INDEX(Assumptions!$B$74:$D$74,Assumptions!$B$5)*INDEX(Assumptions!$B$75:$D$75,Assumptions!$B$5)+(Scenarios!E44-Scenarios!E38)-Scenarios!$E$33 -> 138798.61
A14: Break-even downloads per episode (ads only), by CPM — Scale scenario costs
A15: CPM | B15: Break-even downloads / episode (network average)
A16: 5 | B16: =IFERROR((Scenarios!$E$33-(Scenarios!E44-Scenarios!E38))/(Scenarios!$E$21*(SUMPRODUCT(Scenarios!E14:E20,Assumptions!$F$41:$F$47)/MAX(1,Scenarios!E21))/1000*A16*INDEX(Assumptions!$B$74:$D$74,Assumptions!$B$5)*INDEX(Assumptions!$B$75:$D$75,Assumptions!$B$5)),0) -> -7056.7326
A17: 8 | B17: =IFERROR((Scenarios!$E$33-(Scenarios!E44-Scenarios!E38))/(Scenarios!$E$21*(SUMPRODUCT(Scenarios!E14:E20,Assumptions!$F$41:$F$47)/MAX(1,Scenarios!E21))/1000*A17*INDEX(Assumptions!$B$74:$D$74,Assumptions!$B$5)*INDEX(Assumptions!$B$75:$D$75,Assumptions!$B$5)),0) -> -4410.4579
A18: 10 | B18: =IFERROR((Scenarios!$E$33-(Scenarios!E44-Scenarios!E38))/(Scenarios!$E$21*(SUMPRODUCT(Scenarios!E14:E20,Assumptions!$F$41:$F$47)/MAX(1,Scenarios!E21))/1000*A18*INDEX(Assumptions!$B$74:$D$74,Assumptions!$B$5)*INDEX(Assumptions!$B$75:$D$75,Assumptions!$B$5)),0) -> -3528.3663
A19: 15 | B19: =IFERROR((Scenarios!$E$33-(Scenarios!E44-Scenarios!E38))/(Scenarios!$E$21*(SUMPRODUCT(Scenarios!E14:E20,Assumptions!$F$41:$F$47)/MAX(1,Scenarios!E21))/1000*A19*INDEX(Assumptions!$B$74:$D$74,Assumptions!$B$5)*INDEX(Assumptions!$B$75:$D$75,Assumptions!$B$5)),0) -> -2352.2442
A20: 20 | B20: =IFERROR((Scenarios!$E$33-(Scenarios!E44-Scenarios!E38))/(Scenarios!$E$21*(SUMPRODUCT(Scenarios!E14:E20,Assumptions!$F$41:$F$47)/MAX(1,Scenarios!E21))/1000*A20*INDEX(Assumptions!$B$74:$D$74,Assumptions!$B$5)*INDEX(Assumptions!$B$75:$D$75,Assumptions!$B$5)),0) -> -1764.1831
A21: 25 | B21: =IFERROR((Scenarios!$E$33-(Scenarios!E44-Scenarios!E38))/(Scenarios!$E$21*(SUMPRODUCT(Scenarios!E14:E20,Assumptions!$F$41:$F$47)/MAX(1,Scenarios!E21))/1000*A21*INDEX(Assumptions!$B$74:$D$74,Assumptions!$B$5)*INDEX(Assumptions!$B$75:$D$75,Assumptions!$B$5)),0) -> -1411.3465
A22: 30 | B22: =IFERROR((Scenarios!$E$33-(Scenarios!E44-Scenarios!E38))/(Scenarios!$E$21*(SUMPRODUCT(Scenarios!E14:E20,Assumptions!$F$41:$F$47)/MAX(1,Scenarios!E21))/1000*A22*INDEX(Assumptions!$B$74:$D$74,Assumptions!$B$5)*INDEX(Assumptions!$B$75:$D$75,Assumptions!$B$5)),0) -> -1176.1221

Sheet Sources
A1: Sources
A2: Full citations with links: docs/research/facts-and-figures.md (IDs F-...).
A4: ID | B4: What
A5: F-LLM | B5: Anthropic API list prices by tier, web search $10/1k, batch 50% off, cache reads 0.1× (Oct 2026)
A6: F-TTS | B6: ElevenLabs pricing page: Creator $22/121k, Pro $99/600k, Scale $299/1.8M, Business $990/6M credits
A7: F-HOST | B7: Podcast host plans with dynamic ad insertion and programmatic marketplaces
A8: F-ADS | B8: Podcast CPM benchmarks (programmatic ~$5–$25), fill and revenue share
A9: F-LEGAL | B9: Media liability insurance (~$78/mo avg, Insureon); USPTO $350/class; DBA fees
A10: F-DATA | B10: RSS, GDELT, CourtListener free tiers; paid news APIs
A11: inference | B11: Downloads per episode, sponsor counts, B2B/API/services volumes and rates are planning estimates
